TASK [Create an Instance on AWS] ***************************************************************************************************************************************************************************
An exception occurred during task execution. To see the full traceback, use -vvv. The error was: <Response><Errors><Error><Code>AuthFailure</Code><Message>AWS was not able to validate the provided access credentials</Message></Error></Errors><RequestID>a6d5f28e-55ef-4268-a854-73f5c680a580</RequestID></Response>
fatal: [localhost]: FAILED! => {"changed": false, "failed": true, "module_stderr": "Traceback (most recent call last):\n  File \"/tmp/ansible_pmhCfo/ansible_module_ec2.py\", line 1652, in <module>\n    main()\n  File \"/tmp/ansible_pmhCfo/ansible_module_ec2.py\", line 1643, in main\n    (tagged_instances, instance_dict_array, new_instance_ids, changed) = enforce_count(module, ec2, vpc)\n  File \"/tmp/ansible_pmhCfo/ansible_module_ec2.py\", line 909, in enforce_count\n    reservations, instances = find_running_instances_by_count_tag(module, ec2, count_tag, zone)\n  File \"/tmp/ansible_pmhCfo/ansible_module_ec2.py\", line 622, in find_running_instances_by_count_tag\n    reservations = get_reservations(module, ec2, tags=count_tag, state=\"running\", zone=zone)\n  File \"/tmp/ansible_pmhCfo/ansible_module_ec2.py\", line 681, in get_reservations\n    results = ec2.get_all_instances(filters=filters)\n  File \"/usr/lib/python2.7/site-packages/boto-2.48.0-py2.7.egg/boto/ec2/connection.py\", line 585, in get_all_instances\n    max_results=max_results)\n  File \"/usr/lib/python2.7/site-packages/boto-2.48.0-py2.7.egg/boto/ec2/connection.py\", line 681, in get_all_reservations\n    [('item', Reservation)], verb='POST')\n  File \"/usr/lib/python2.7/site-packages/boto-2.48.0-py2.7.egg/boto/connection.py\", line 1186, in get_list\n    raise self.ResponseError(response.status, response.reason, body)\nboto.exception.EC2ResponseError: EC2ResponseError: 401 Unauthorized\n<?xml version=\"1.0\" encoding=\"UTF-8\"?>\n<Response><Errors><Error><Code>AuthFailure</Code><Message>AWS was not able to validate the provided access credentials</Message></Error></Errors><RequestID>a6d5f28e-55ef-4268-a854-73f5c680a580</RequestID></Response>\n", "module_stdout": "", "msg": "MODULE FAILURE", "rc": 0}
 [WARNING]: Could not create retry file '/etc/ansible/development/ansible-aws/playbooks/demo_setup.retry'.         [Errno 13] Permission denied: u'/etc/ansible/development/ansible-
aws/playbooks/demo_setup.retry'
